<?xml version="1.0"?>
<robot name="wholeR">

  <!-- 基础世界链接 -->
  <link name="world"/>

  <!-- X轴移动平台 -->
  <link name="x_axis">
    <visual>
      <geometry>
        <box size="2.2 0.2 0.2"/>
      </geometry>
      <material name="red">
        <color rgba="1 0 0 1"/>
      </material>
    </visual>
    <collision>
      <geometry>
        <box size="2.2 0.2 0.2"/>
      </geometry>
    </collision>
    <inertial>
      <mass value="10.0"/>
      <inertia ixx="0.5" ixy="0" ixz="0" iyy="0.5" iyz="0" izz="0.5"/>
    </inertial>
  </link>

  <joint name="x_joint" type="prismatic">
    <parent link="world"/>
    <child link="x_axis"/>
    <axis xyz="1 0 0"/>
    <limit lower="-1.0" upper="1.0" effort="1000" velocity="2.0"/>
    <dynamics damping="1"/>
  </joint>

  <!-- Y轴移动平台 -->
  <link name="y_axis">
    <visual>
      <geometry>
        <box size="0.2 2.2 0.2"/>
      </geometry>
      <material name="green">
        <color rgba="0 1 0 1"/>
      </material>
    </visual>
    <collision>
      <geometry>
        <box size="0.2 2.2 0.2"/>
      </geometry>
    </collision>
    <inertial>
      <mass value="8.0"/>
      <inertia ixx="0.4" ixy="0" ixz="0" iyy="0.4" iyz="0" izz="0.4"/>
    </inertial>
  </link>

  <joint name="y_joint" type="prismatic">
    <parent link="x_axis"/>
    <child link="y_axis"/>
    <axis xyz="0 1 0"/>
    <limit lower="-1.0" upper="1.0" effort="1000" velocity="2.0"/>
    <dynamics damping="1"/>
  </joint>

  <!-- Z轴移动平台 -->
  <link name="z_axis">
    <visual>
      <geometry>
        <box size="0.2 0.2 2.2"/>
      </geometry>
      <material name="blue">
        <color rgba="0 0 1 1"/>
      </material>
    </visual>
    <collision>
      <geometry>
        <box size="0.2 0.2 2.2"/>
      </geometry>
    </collision>
    <inertial>
      <mass value="6.0"/>
      <inertia ixx="0.3" ixy="0" ixz="0" iyy="0.3" iyz="0" izz="0.3"/>
    </inertial>
  </link>

  <joint name="z_joint" type="prismatic">
    <parent link="y_axis"/>
    <child link="z_axis"/>
    <axis xyz="0 0 1"/>
    <limit lower="-1" upper="1" effort="1000" velocity="1.5"/>
    <dynamics damping="0.7"/>
  </joint>

  <!-- 末端执行器（可视化标记） -->
  <link name="end_effector">
    <visual>
      <geometry>
        <sphere radius="0.1"/>
      </geometry>
      <material name="yellow">
        <color rgba="1 1 0 1"/>
      </material>
    </visual>
    <collision>
      <geometry>
        <sphere radius="0.1"/>
      </geometry>
    </collision>
    <inertial>
      <mass value="0.5"/>
      <inertia ixx="0.01" ixy="0" ixz="0" iyy="0.01" iyz="0" izz="0.01"/>
    </inertial>
  </link>

  <joint name="ee_fixed_joint" type="fixed">
    <parent link="z_axis"/>
    <child link="end_effector"/>
    <origin xyz="0 0 -1.1"/>
  </joint>



  <!-- 第一旋转关节（绕X轴） -->
  <link name="joint_x">
    <visual>
      <geometry>
        <cylinder radius="0.02" length="0.1"/>
      </geometry>
      <material name="blue">
        <color rgba="0 0 1 1"/>
      </material>
    </visual>
    <inertial>
      <mass value="0.01"/>
      <inertia ixx="0.001" ixy="0" ixz="0" iyy="0.001" iyz="0" izz="0.001"/>
    </inertial>
  </link>

  <joint name="joint_x_axis" type="revolute">
    <parent link="end_effector"/>
    <child link="joint_x"/>
    <axis xyz="1 0 0"/>  <!-- X轴旋转 -->
    <limit lower="-3.14" upper="3.14" effort="100" velocity="10"/>
    <dynamics damping="2"/> <!-- 增加旋转阻尼 -->
  </joint>

  <!-- 第二旋转关节（绕Y轴） -->
  <link name="joint_y">
    <visual>
      <geometry>
        <cylinder radius="0.02" length="0.1"/>
      </geometry>
      <material name="green">
        <color rgba="0 1 0 1"/>
      </material>
    </visual>
    <inertial>
      <mass value="0.01"/>
      <inertia ixx="0.001" ixy="0" ixz="0" iyy="0.001" iyz="0" izz="0.001"/>
    </inertial>
  </link>

  <joint name="joint_y_axis" type="revolute">
    <parent link="joint_x"/>
    <child link="joint_y"/>
    <axis xyz="0 1 0"/>  <!-- Y轴旋转 -->
    <limit lower="-3.14" upper="3.14" effort="100" velocity="10"/>
    <dynamics damping="2"/> <!-- 增加旋转阻尼 -->
  </joint>

  <!-- 摆杆 -->
  <link name="rod">
    <visual>
      <geometry>
        <cylinder radius="0.01" length="1.0"/>
      </geometry>
      <material name="gray">
        <color rgba="0.5 0.5 0.5 1"/>
      </material>
    </visual>
    <collision>
      <geometry>
        <cylinder radius="0.01" length="1.0"/>
      </geometry>
    </collision>
    <inertial>
      <mass value="0.1"/>
      <inertia ixx="0.01" ixy="0" ixz="0" iyy="0.01" iyz="0" izz="0.01"/>
    </inertial>
  </link>

  <joint name="joint_rod" type="fixed">
    <parent link="joint_y"/>
    <child link="rod"/>
    <origin xyz="0 0 -0.5"/>  <!-- 摆杆连接点 -->
  </joint>

  <!-- 钢球 -->
  <link name="ball">
    <visual>
      <geometry>
        <sphere radius="0.1"/>
      </geometry>
      <material name="metal">
        <color rgba="0.7 0.7 0.8 1"/>
      </material>
    </visual>
    <collision>
      <geometry>
        <sphere radius="0.1"/>
      </geometry>
    </collision>
    <inertial>
      <mass value="2.0"/>  <!-- 钢球质量较大 -->
      <inertia ixx="0.1" ixy="0" ixz="0" iyy="0.1" iyz="0" izz="0.1"/>
    </inertial>
  </link>

  <joint name="joint_ball" type="fixed">
    <parent link="rod"/>
    <child link="ball"/>
    <origin xyz="0 0 -0.5"/>  <!-- 钢球位于摆杆末端 -->
  </joint>
</robot>